<?xml version="1.0"?>
<robot name="my_robot">

<!-- ========== LINKS ========== -->

<link name="base_footprint"/>

<link name="base_link">
  <inertial>
    <mass value="5.0"/>
    <origin xyz="0 0 0" rpy="0 0 0"/>
    <inertia ixx="0.1" ixy="0" ixz="0" iyy="0.1" iyz="0" izz="0.1"/>
  </inertial>

  <visual>
    <origin xyz="0 0 0.1"/>
    <geometry>
      <box size="0.6 0.4 0.2"/>
    </geometry>
  </visual>

  <collision>
    <origin xyz="0 0 0.1"/>
    <geometry>
      <box size="0.6 0.4 0.2"/>
    </geometry>
  </collision>
</link>

<link name="left_wheel">
  <inertial>
    <mass value="1.0"/>
    <inertia ixx="0.001" ixy="0" ixz="0" iyy="0.001" iyz="0" izz="0.001"/>
  </inertial>

  <visual>
    <geometry>
      <cylinder radius="0.1" length="0.05"/>
    </geometry>
  </visual>

  <collision>
    <geometry>
      <cylinder radius="0.1" length="0.05"/>
    </geometry>
  </collision>
</link>

<link name="right_wheel">
  <inertial>
    <mass value="1.0"/>
    <inertia ixx="0.001" ixy="0" ixz="0" iyy="0.001" iyz="0" izz="0.001"/>
  </inertial>

  <visual>
    <geometry>
      <cylinder radius="0.1" length="0.05"/>
    </geometry>
  </visual>

  <collision>
    <geometry>
      <cylinder radius="0.1" length="0.05"/>
    </geometry>
  </collision>
</link>

<link name="caster_wheel">
  <collision>
    <geometry>
      <sphere radius="0.05"/>
    </geometry>
  </collision>
</link>

<!-- ========== JOINTS ========== -->

<joint name="base_joint" type="fixed">
  <parent link="base_footprint"/>
  <child link="base_link"/>
</joint>

<joint name="left_wheel_joint" type="continuous">
  <parent link="base_link"/>
  <child link="left_wheel"/>
  <origin xyz="0 0.23 0.1"/>
  <axis xyz="0 0 1"/>
</joint>

<joint name="right_wheel_joint" type="continuous">
  <parent link="base_link"/>
  <child link="right_wheel"/>
  <origin xyz="0 -0.23 0.1"/>
  <axis xyz="0 0 1"/>
</joint>

<joint name="caster_joint" type="fixed">
  <parent link="base_link"/>
  <child link="caster_wheel"/>
  <origin xyz="-0.25 0 0.05"/>
</joint>

<!-- ========== GAZEBO DIFF DRIVE PLUGIN ========== -->

<gazebo>
  <plugin name="diff_drive" filename="libgazebo_ros_diff_drive.so">

    <ros>
      <namespace>/</namespace>
    </ros>

    <left_joint>left_wheel_joint</left_joint>
    <right_joint>right_wheel_joint</right_joint>

    <wheel_separation>0.46</wheel_separation>
    <wheel_diameter>0.2</wheel_diameter>

    <command_topic>/cmd_vel</command_topic>
    <odometry_topic>/odom</odometry_topic>

    <robot_base_frame>base_footprint</robot_base_frame>

    <publish_odom>true</publish_odom>
    <publish_odom_tf>true</publish_odom_tf>

    <update_rate>50</update_rate>

  </plugin>
</gazebo>

</robot>
