<?xml version="1.0"?>
<robot name="my_robot">

  <!-- ================= MATERIALS ================= -->

  <material name="grey">
    <color rgba="0.7 0.7 0.7 1"/>
  </material>

  <material name="green">
    <color rgba="0 0.6 0 1"/>
  </material>

  <material name="white">
    <color rgba="1 1 1 1"/>
  </material>

  <!-- ================= BASE ================= -->

  <link name="base_footprint"/>

  <link name="base_link">

    <inertial>
      <origin xyz="0 0 0" rpy="0 0 0"/>
      <mass value="5.0"/>

      <inertia
        ixx="0.1"
        ixy="0"
        ixz="0"
        iyy="0.1"
        iyz="0"
        izz="0.1"/>
    </inertial>

    <visual>
      <origin xyz="0 0 0.1" rpy="0 0 0"/>

      <geometry>
        <box size="0.6 0.4 0.2"/>
      </geometry>

      <material name="green"/>
    </visual>

    <collision>
      <origin xyz="0 0 0.1" rpy="0 0 0"/>

      <geometry>
        <box size="0.6 0.4 0.2"/>
      </geometry>
    </collision>

  </link>

  <!-- ================= LIDAR ================= -->

  <link name="lidar">

    <visual>
      <geometry>
        <cylinder radius="0.1" length="0.05"/>
      </geometry>

      <material name="white"/>
    </visual>

  </link>

  <!-- ================= LEFT WHEEL ================= -->

  <link name="left_wheel">

    <inertial>
      <mass value="1.0"/>

      <inertia
        ixx="0.001"
        ixy="0"
        ixz="0"
        iyy="0.001"
        iyz="0"
        izz="0.001"/>
    </inertial>

    <visual>
      <origin xyz="0 0 0" rpy="1.57 0 0"/>

      <geometry>
        <cylinder radius="0.1" length="0.05"/>
      </geometry>

      <material name="grey"/>
    </visual>

    <collision>
      <origin xyz="0 0 0" rpy="1.57 0 0"/>

      <geometry>
        <cylinder radius="0.1" length="0.05"/>
      </geometry>
    </collision>

  </link>

  <!-- ================= RIGHT WHEEL ================= -->

  <link name="right_wheel">

    <inertial>
      <mass value="1.0"/>

      <inertia
        ixx="0.001"
        ixy="0"
        ixz="0"
        iyy="0.001"
        iyz="0"
        izz="0.001"/>
    </inertial>

    <visual>
      <origin xyz="0 0 0" rpy="1.57 0 0"/>

      <geometry>
        <cylinder radius="0.1" length="0.05"/>
      </geometry>

      <material name="grey"/>
    </visual>

    <collision>
      <origin xyz="0 0 0" rpy="1.57 0 0"/>

      <geometry>
        <cylinder radius="0.1" length="0.05"/>
      </geometry>
    </collision>

  </link>

  <!-- ================= CASTER ================= -->

  <link name="caster_wheel">

    <visual>
      <geometry>
        <sphere radius="0.05"/>
      </geometry>

      <material name="grey"/>
    </visual>

    <collision>
      <geometry>
        <sphere radius="0.05"/>
      </geometry>
    </collision>

  </link>

  <!-- ================= JOINTS ================= -->

  <joint name="base_joint" type="fixed">
    <parent link="base_footprint"/>
    <child link="base_link"/>

    <origin xyz="0 0 0.1" rpy="0 0 0"/>
  </joint>

  <joint name="base_lidar_joint" type="fixed">
    <parent link="base_link"/>
    <child link="lidar"/>

    <origin xyz="0 0 0.225" rpy="0 0 0"/>
  </joint>

  <!-- IMPORTANT: axis must be 0 1 0 -->

  <joint name="base_left_wheel_joint" type="continuous">
    <parent link="base_link"/>
    <child link="left_wheel"/>

    <origin xyz="-0.15 0.225 0" rpy="0 0 0"/>

    <axis xyz="0 1 0"/>
  </joint>

  <joint name="base_right_wheel_joint" type="continuous">
    <parent link="base_link"/>
    <child link="right_wheel"/>

    <origin xyz="-0.15 -0.225 0" rpy="0 0 0"/>

    <axis xyz="0 1 0"/>
  </joint>

  <joint name="base_caster_wheel_joint" type="fixed">
    <parent link="base_link"/>
    <child link="caster_wheel"/>

    <origin xyz="0.2 0 -0.05" rpy="0 0 0"/>
  </joint>

  <!-- ================= GAZEBO FRICTION ================= -->

  <gazebo reference="left_wheel">
    <mu1>1.0</mu1>
    <mu2>1.0</mu2>
  </gazebo>

  <gazebo reference="right_wheel">
    <mu1>1.0</mu1>
    <mu2>1.0</mu2>
  </gazebo>

  <!-- ================= DIFF DRIVE ================= -->

  <gazebo>
    <plugin name="diff_drive" filename="libgazebo_ros_diff_drive.so">

      <ros>
        <namespace>/</namespace>
      </ros>

      <left_joint>base_left_wheel_joint</left_joint>
      <right_joint>base_right_wheel_joint</right_joint>

      <wheel_separation>0.45</wheel_separation>
      <wheel_diameter>0.2</wheel_diameter>

      <command_topic>/cmd_vel</command_topic>
      <odometry_topic>/odom</odometry_topic>

      <robot_base_frame>base_footprint</robot_base_frame>

      <publish_odom>true</publish_odom>
      <publish_odom_tf>true</publish_odom_tf>

      <update_rate>50</update_rate>

    </plugin>
  </gazebo>
  <!-- ================= LIDAR SENSOR ================= -->

<gazebo reference="lidar">

  <sensor name="lidar_sensor" type="ray">

    <pose>0 0 0 0 0 0</pose>

    <visualize>true</visualize>

    <update_rate>10</update_rate>

    <ray>

      <scan>

        <horizontal>

          <samples>360</samples>

          <resolution>1</resolution>

          <min_angle>-3.14</min_angle>

          <max_angle>3.14</max_angle>

        </horizontal>

      </scan>

      <range>

        <min>0.12</min>

        <max>8.0</max>

        <resolution>0.01</resolution>

      </range>

    </ray>

    <plugin name="gazebo_ros_laser" filename="libgazebo_ros_ray_sensor.so">

      <ros>
        <remapping>~/out:=scan</remapping>
      </ros>

      <output_type>sensor_msgs/LaserScan</output_type>

      <frame_name>lidar</frame_name>

    </plugin>

  </sensor>

</gazebo>
</robot>
